Workbook

Sheet Read Me
A1: ROOTWAKE — Species & Systems Database v0.1
A3: What this is | B3: The master data file for Rootwake's flora. Every recipe, order, and market price reads from these tables. The game repo (SacredGrove) keeps this workbook in data/ and reads the Species and Plants tabs with `npm run data`, which validates them and writes src/data/plants.gen.json.
A4: Design pyramid | B4: Base ≈ filler/food/carriers; Workhorse = reliable single actions; Rare Active = signature effects. Target ratio ~60/30/10 by count; see Stats tab (live formulas).
A5: Setting | B5: Southern Illinois-style ecology (Shawnee Hills, bottomlands, tallgrass remnants, limestone bluffs) plus one fictional biome — the Mycelial Hollow — where the Network surfaces. Real species carry folk-traditional uses as GAME effects only; no real dosing is modeled.
A6: Hidden values | B6: Compound codes + strength (1–10) are hidden from the player. Taste, smell, drying, burning and extraction each reveal one layer in the Field Journal.
A7: Toxicity | B7: 0–10. ≥5 = harmful in game; ≥9 = lethal species, sellable only to licensed buyers, and handling without gloves applies a status. Taste column shows DO NOT TASTE for lethal species — tasting them is an in-game death/injury event.
A8: Months | B8: 1–12. If Harvest Start > Harvest End the window wraps the new year (e.g. 10→3 = Oct–Mar). Seed Month 0 = propagated by division/spores only.
A9: Editing | B9: Blue text = hand-entered inputs; edit freely. Black = formulas (Seasonal Calendar, Stats, Recipe value). Add species by appending rows to the Species tab; the calendar and stats extend if you copy the formula rows down.
A10: Fictional species | B10: Marked '(fictional)' in the Latin name. All other species are real and native or naturalized to the Midwest.
A11: Plants tab | B11: Ecology for the game world: one row per living plant (Species rows are harvestable PRODUCTS and join on Latin Name, so Common Mullein + Mullein Flower share one plant). Light/moisture/disturbance/fertility are 0-1 optimum + tolerance (a Gaussian width). DOY = day of year (Mar 1 = 60, Jul 1 = 182, Oct 1 = 274); a green-up later than dieback means the plant is active across winter (winter annuals). C-value approximates Illinois Floristic Quality conservatism: 6+ only grows on never-plowed ground. Mow Tolerance 0-3 = the heaviest mowing it survives (3 = weekly lawn). The game reads this tab: run `npm run data` in SacredGrove after editing.

Sheet Species
A1: ID | B1: Common Name | C1: Latin Name | D1: Tier | E1: Biome | F1: Part Used | G1: Harvest Start | H1: Harvest End | I1: Seed Month | J1: Compound 1 | K1: Str 1 | L1: Compound 2 | M1: Str 2 | N1: Compound 3 | O1: Str 3 | P1: Toxicity (0-10) | Q1: Taste (journal) | R1: Smell (journal) | S1: Primary Use / Effect | T1: Rarity (1-5) | U1: Base Price (c) | V1: Shelf Life (days) | W1: On Plants tab?
A2: SP001 | B2: Lamb's Quarters | C2: Chenopodium album | D2: Base | E2: Disturbed Ground | F2: Leaf | G2: 5 | H2: 8 | I2: 9 | J2: SUG | K2: 3 | L2: ACI | M2: 2 | P2: 1 | Q2: Spinach-like | R2: Earthy | S2: Filler / food | T2: 1 | U2: =ROUND(2*T2^2*IF(D2="Rare Active",6,IF(D2="Workhorse",2,1))+(K2+M2+O2)/2,0) -> 5 | V2: 45 | W2: =IF(COUNTIF(Plants!$A$2:$A$1000,C2)>0,"yes","") -> yes
A3: SP002 | B3: Chickweed | C3: Stellaria media | D3: Base | E3: Disturbed Ground | F3: Whole | G3: 3 | H3: 5 | I3: 5 | J3: MUC | K3: 3 | L3: SAP | M3: 1 | P3: 0 | Q3: Fresh, corn-silk | R3: Faint | S3: Cooling base | T3: 1 | U3: =ROUND(2*T3^2*IF(D3="Rare Active",6,IF(D3="Workhorse",2,1))+(K3+M3+O3)/2,0) -> 4 | V3: 40 | W3: =IF(COUNTIF(Plants!$A$2:$A$1000,C3)>0,"yes","") -> yes
A4: SP003 | B4: Purple Deadnettle | C4: Lamium purpureum | D4: Base | E4: Disturbed Ground | F4: Whole | G4: 3 | H4: 5 | I4: 5 | J4: FLA | K4: 2 | L4: VOL | M4: 1 | P4: 0 | Q4: Grassy | R4: Musty mint | S4: Filler | T4: 1 | U4: =ROUND(2*T4^2*IF(D4="Rare Active",6,IF(D4="Workhorse",2,1))+(K4+M4+O4)/2,0) -> 4 | V4: 40 | W4: =IF(COUNTIF(Plants!$A$2:$A$1000,C4)>0,"yes","") -> yes
A5: SP004 | B5: Henbit | C5: Lamium amplexicaule | D5: Base | E5: Disturbed Ground | F5: Whole | G5: 3 | H5: 5 | I5: 5 | J5: FLA | K5: 2 | P5: 0 | Q5: Mild | R5: Faint | S5: Filler | T5: 1 | U5: =ROUND(2*T5^2*IF(D5="Rare Active",6,IF(D5="Workhorse",2,1))+(K5+M5+O5)/2,0) -> 3 | V5: 40 | W5: =IF(COUNTIF(Plants!$A$2:$A$1000,C5)>0,"yes","") -> yes
A6: SP005 | B6: Dandelion | C6: Taraxacum officinale | D6: Workhorse | E6: Disturbed Ground | F6: Root | G6: 3 | H6: 11 | I6: 5 | J6: BIT | K6: 5 | L6: SUG | M6: 3 | N6: LAT | O6: 2 | P6: 0 | Q6: Bitter | R6: Earthy | S6: Digestive bitter / liver tonic | T6: 1 | U6: =ROUND(2*T6^2*IF(D6="Rare Active",6,IF(D6="Workhorse",2,1))+(K6+M6+O6)/2,0) -> 9 | V6: 120 | W6: =IF(COUNTIF(Plants!$A$2:$A$1000,C6)>0,"yes","") -> yes
A7: SP006 | B7: Common Blue Violet | C7: Viola sororia | D7: Base | E7: Upland Forest | F7: Leaf | G7: 3 | H7: 6 | I7: 6 | J7: MUC | K7: 4 | L7: SAP | M7: 1 | P7: 0 | Q7: Mild, slick | R7: Faint sweet | S7: Thickener | T7: 2 | U7: =ROUND(2*T7^2*IF(D7="Rare Active",6,IF(D7="Workhorse",2,1))+(K7+M7+O7)/2,0) -> 11 | V7: 45 | W7: =IF(COUNTIF(Plants!$A$2:$A$1000,C7)>0,"yes","") -> yes
A8: SP007 | B8: Cleavers | C8: Galium aparine | D8: Base | E8: Bottomland Forest | F8: Whole | G8: 4 | H8: 6 | I8: 6 | J8: COU | K8: 1 | L8: ACI | M8: 2 | P8: 0 | Q8: Green | R8: Hay | S8: Strainer / lymph wash | T8: 1 | U8: =ROUND(2*T8^2*IF(D8="Rare Active",6,IF(D8="Workhorse",2,1))+(K8+M8+O8)/2,0) -> 4 | V8: 40 | W8: =IF(COUNTIF(Plants!$A$2:$A$1000,C8)>0,"yes","") -> yes
A9: SP008 | B9: Wood Sorrel | C9: Oxalis stricta | D9: Base | E9: Disturbed Ground | F9: Leaf | G9: 5 | H9: 10 | I9: 7 | J9: ACI | K9: 5 | P9: 1 | Q9: Sour, lemony | R9: None | S9: Acidifier | T9: 1 | U9: =ROUND(2*T9^2*IF(D9="Rare Active",6,IF(D9="Workhorse",2,1))+(K9+M9+O9)/2,0) -> 5 | V9: 45 | W9: =IF(COUNTIF(Plants!$A$2:$A$1000,C9)>0,"yes","") -> yes
A10: SP009 | B10: Sheep Sorrel | C10: Rumex acetosella | D10: Base | E10: Prairie | F10: Leaf | G10: 4 | H10: 7 | I10: 7 | J10: ACI | K10: 4 | L10: TAN | M10: 2 | P10: 1 | Q10: Sour | R10: None | S10: Acidifier | T10: 1 | U10: =ROUND(2*T10^2*IF(D10="Rare Active",6,IF(D10="Workhorse",2,1))+(K10+M10+O10)/2,0) -> 5 | V10: 45 | W10: =IF(COUNTIF(Plants!$A$2:$A$1000,C10)>0,"yes","") -> yes
A11: SP010 | B11: Curly Dock | C11: Rumex crispus | D11: Workhorse | E11: Disturbed Ground | F11: Root | G11: 9 | H11: 11 | I11: 8 | J11: TAN | K11: 4 | L11: GLY | M11: 3 | N11: PIG | O11: 2 | P11: 1 | Q11: Bitter, astringent | R11: Earthy | S11: Purgative / yellow dye | T11: 1 | U11: =ROUND(2*T11^2*IF(D11="Rare Active",6,IF(D11="Workhorse",2,1))+(K11+M11+O11)/2,0) -> 9 | V11: 120 | W11: =IF(COUNTIF(Plants!$A$2:$A$1000,C11)>0,"yes","") -> yes
A12: SP011 | B12: Red Clover | C12: Trifolium pratense | D12: Base | E12: Prairie | F12: Flower | G12: 5 | H12: 8 | I12: 8 | J12: FLA | K12: 3 | L12: COU | M12: 2 | N12: SUG | O12: 2 | P12: 0 | Q12: Sweet | R12: Honeyed | S12: Flavor mask (sweet) | T12: 1 | U12: =ROUND(2*T12^2*IF(D12="Rare Active",6,IF(D12="Workhorse",2,1))+(K12+M12+O12)/2,0) -> 6 | V12: 30 | W12: =IF(COUNTIF(Plants!$A$2:$A$1000,C12)>0,"yes","") -> yes
A13: SP012 | B13: White Clover | C13: Trifolium repens | D13: Base | E13: Disturbed Ground | F13: Flower | G13: 5 | H13: 9 | I13: 8 | J13: SUG | K13: 2 | L13: FLA | M13: 1 | P13: 0 | Q13: Sweet | R13: Faint | S13: Bee forage / filler | T13: 1 | U13: =ROUND(2*T13^2*IF(D13="Rare Active",6,IF(D13="Workhorse",2,1))+(K13+M13+O13)/2,0) -> 4 | V13: 30 | W13: =IF(COUNTIF(Plants!$A$2:$A$1000,C13)>0,"yes","") -> yes
A14: SP013 | B14: Wild Strawberry | C14: Fragaria virginiana | D14: Base | E14: Prairie | F14: Fruit | G14: 5 | H14: 6 | I14: 6 | J14: SUG | K14: 4 | L14: ACI | M14: 2 | N14: ANT | O14: 2 | P14: 0 | Q14: Sweet-tart | R14: Fruity | S14: Flavor mask (fruit) | T14: 2 | U14: =ROUND(2*T14^2*IF(D14="Rare Active",6,IF(D14="Workhorse",2,1))+(K14+M14+O14)/2,0) -> 12 | V14: 10 | W14: =IF(COUNTIF(Plants!$A$2:$A$1000,C14)>0,"yes","") -> yes
A15: SP014 | B15: Riverbank Grape | C15: Vitis riparia | D15: Base | E15: Riverbank | F15: Fruit | G15: 8 | H15: 10 | I15: 9 | J15: SUG | K15: 4 | L15: ACI | M15: 3 | N15: ANT | O15: 3 | P15: 0 | Q15: Tart | R15: Musky | S15: Ferment base | T15: 2 | U15: =ROUND(2*T15^2*IF(D15="Rare Active",6,IF(D15="Workhorse",2,1))+(K15+M15+O15)/2,0) -> 13 | V15: 10 | W15: =IF(COUNTIF(Plants!$A$2:$A$1000,C15)>0,"yes","") -> yes
A16: SP015 | B16: Black Raspberry | C16: Rubus occidentalis | D16: Base | E16: Oak Savanna | F16: Fruit | G16: 6 | H16: 7 | I16: 7 | J16: SUG | K16: 4 | L16: ANT | M16: 4 | P16: 0 | Q16: Sweet | R16: Berry | S16: Dye: purple / flavor | T16: 2 | U16: =ROUND(2*T16^2*IF(D16="Rare Active",6,IF(D16="Workhorse",2,1))+(K16+M16+O16)/2,0) -> 12 | V16: 10 | W16: =IF(COUNTIF(Plants!$A$2:$A$1000,C16)>0,"yes","") -> yes
A17: SP016 | B17: Blackberry Leaf | C17: Rubus allegheniensis | D17: Base | E17: Oak Savanna | F17: Leaf | G17: 5 | H17: 9 | I17: 8 | J17: TAN | K17: 5 | P17: 0 | Q17: Astringent | R17: Tea-like | S17: Astringent base | T17: 2 | U17: =ROUND(2*T17^2*IF(D17="Rare Active",6,IF(D17="Workhorse",2,1))+(K17+M17+O17)/2,0) -> 11 | V17: 45 | W17: =IF(COUNTIF(Plants!$A$2:$A$1000,C17)>0,"yes","") -> yes
A18: SP017 | B18: Red Mulberry | C18: Morus rubra | D18: Base | E18: Bottomland Forest | F18: Fruit | G18: 6 | H18: 7 | I18: 7 | J18: SUG | K18: 5 | L18: ANT | M18: 3 | P18: 0 | Q18: Very sweet | R18: Fruity | S18: Sweetener / dye | T18: 2 | U18: =ROUND(2*T18^2*IF(D18="Rare Active",6,IF(D18="Workhorse",2,1))+(K18+M18+O18)/2,0) -> 12 | V18: 10 | W18: =IF(COUNTIF(Plants!$A$2:$A$1000,C18)>0,"yes","") -> yes
A19: SP018 | B19: Pawpaw | C19: Asimina triloba | D19: Base | E19: Bottomland Forest | F19: Fruit | G19: 9 | H19: 10 | I19: 10 | J19: SUG | K19: 5 | P19: 1 | Q19: Custard, tropical | R19: Banana | S19: Sweetener (spoils fast) | T19: 3 | U19: =ROUND(2*T19^2*IF(D19="Rare Active",6,IF(D19="Workhorse",2,1))+(K19+M19+O19)/2,0) -> 21 | V19: 10 | W19: =IF(COUNTIF(Plants!$A$2:$A$1000,C19)>0,"yes","")
A20: SP019 | B20: Persimmon | C20: Diospyros virginiana | D20: Base | E20: Oak Savanna | F20: Fruit | G20: 10 | H20: 12 | I20: 11 | J20: SUG | K20: 6 | L20: TAN | M20: 3 | P20: 0 | Q20: Honey-sweet when ripe, chalky if not | R20: Date | S20: Sweetener | T20: 2 | U20: =ROUND(2*T20^2*IF(D20="Rare Active",6,IF(D20="Workhorse",2,1))+(K20+M20+O20)/2,0) -> 13 | V20: 10 | W20: =IF(COUNTIF(Plants!$A$2:$A$1000,C20)>0,"yes","") -> yes
A21: SP020 | B21: Shagbark Hickory Nut | C21: Carya ovata | D21: Base | E21: Upland Forest | F21: Seed | G21: 9 | H21: 10 | I21: 10 | J21: SUG | K21: 3 | L21: RES | M21: 1 | P21: 0 | Q21: Buttery | R21: Nutty | S21: Oil press | T21: 3 | U21: =ROUND(2*T21^2*IF(D21="Rare Active",6,IF(D21="Workhorse",2,1))+(K21+M21+O21)/2,0) -> 20 | V21: 300 | W21: =IF(COUNTIF(Plants!$A$2:$A$1000,C21)>0,"yes","") -> yes
A22: SP021 | B22: Black Walnut Hull | C22: Juglans nigra | D22: Workhorse | E22: Upland Forest | F22: Fruit | G22: 9 | H22: 10 | I22: 10 | J22: TAN | K22: 6 | L22: PIG | M22: 6 | P22: 2 | Q22: Harsh, bitter | R22: Citrus-resin | S22: Dye: brown / antifungal | T22: 3 | U22: =ROUND(2*T22^2*IF(D22="Rare Active",6,IF(D22="Workhorse",2,1))+(K22+M22+O22)/2,0) -> 42 | V22: 10 | W22: =IF(COUNTIF(Plants!$A$2:$A$1000,C22)>0,"yes","") -> yes
A23: SP022 | B23: White Oak Acorn | C23: Quercus alba | D23: Base | E23: Oak Savanna | F23: Seed | G23: 9 | H23: 11 | I23: 10 | J23: TAN | K23: 5 | L23: SUG | M23: 4 | P23: 1 | Q23: Astringent | R23: Nutty | S23: Starch (leach first) | T23: 2 | U23: =ROUND(2*T23^2*IF(D23="Rare Active",6,IF(D23="Workhorse",2,1))+(K23+M23+O23)/2,0) -> 13 | V23: 300 | W23: =IF(COUNTIF(Plants!$A$2:$A$1000,C23)>0,"yes","") -> yes
A24: SP023 | B24: White Oak Bark | C24: Quercus alba | D24: Workhorse | E24: Oak Savanna | F24: Bark | G24: 3 | H24: 5 | I24: 0 | J24: TAN | K24: 8 | P24: 0 | Q24: Extremely astringent | R24: Woody | S24: Wound wash / leather tanning | T24: 3 | U24: =ROUND(2*T24^2*IF(D24="Rare Active",6,IF(D24="Workhorse",2,1))+(K24+M24+O24)/2,0) -> 40 | V24: 240 | W24: =IF(COUNTIF(Plants!$A$2:$A$1000,C24)>0,"yes","") -> yes
A25: SP024 | B25: Shagbark Hickory Bark | C25: Carya ovata | D25: Base | E25: Upland Forest | F25: Bark | G25: 1 | H25: 12 | I25: 0 | J25: TAN | K25: 3 | L25: VOL | M25: 2 | N25: SUG | O25: 2 | P25: 0 | Q25: Smoky-sweet | R25: Maple-smoke | S25: Syrup base | T25: 3 | U25: =ROUND(2*T25^2*IF(D25="Rare Active",6,IF(D25="Workhorse",2,1))+(K25+M25+O25)/2,0) -> 22 | V25: 240 | W25: =IF(COUNTIF(Plants!$A$2:$A$1000,C25)>0,"yes","") -> yes
A26: SP025 | B26: Sugar Maple Sap | C26: Acer saccharum | D26: Base | E26: Upland Forest | F26: Sap | G26: 2 | H26: 3 | I26: 0 | J26: SUG | K26: 6 | P26: 0 | Q26: Faintly sweet | R26: None | S26: Syrup / solvent | T26: 3 | U26: =ROUND(2*T26^2*IF(D26="Rare Active",6,IF(D26="Workhorse",2,1))+(K26+M26+O26)/2,0) -> 21 | V26: 7 | W26: =IF(COUNTIF(Plants!$A$2:$A$1000,C26)>0,"yes","") -> yes
A27: SP026 | B27: Box Elder Sap | C27: Acer negundo | D27: Base | E27: Riverbank | F27: Sap | G27: 2 | H27: 3 | I27: 0 | J27: SUG | K27: 4 | P27: 0 | Q27: Faint | R27: None | S27: Syrup (weak) | T27: 2 | U27: =ROUND(2*T27^2*IF(D27="Rare Active",6,IF(D27="Workhorse",2,1))+(K27+M27+O27)/2,0) -> 10 | V27: 7 | W27: =IF(COUNTIF(Plants!$A$2:$A$1000,C27)>0,"yes","")
A28: SP027 | B28: Cattail Rhizome | C28: Typha latifolia | D28: Base | E28: Wetland | F28: Rhizome | G28: 10 | H28: 3 | I28: 8 | J28: SUG | K28: 5 | P28: 0 | Q28: Starchy | R28: Mud | S28: Starch / binder | T28: 2 | U28: =ROUND(2*T28^2*IF(D28="Rare Active",6,IF(D28="Workhorse",2,1))+(K28+M28+O28)/2,0) -> 11 | V28: 120 | W28: =IF(COUNTIF(Plants!$A$2:$A$1000,C28)>0,"yes","")
A29: SP028 | B29: Cattail Pollen | C29: Typha latifolia | D29: Base | E29: Wetland | F29: Flower | G29: 6 | H29: 6 | I29: 0 | J29: SUG | K29: 3 | L29: FLA | M29: 1 | P29: 0 | Q29: Corn-like | R29: Faint | S29: Flour / dusting powder | T29: 2 | U29: =ROUND(2*T29^2*IF(D29="Rare Active",6,IF(D29="Workhorse",2,1))+(K29+M29+O29)/2,0) -> 10 | V29: 30 | W29: =IF(COUNTIF(Plants!$A$2:$A$1000,C29)>0,"yes","")
A30: SP029 | B30: Broadleaf Arrowhead | C30: Sagittaria latifolia | D30: Base | E30: Wetland | F30: Rhizome | G30: 9 | H30: 11 | I30: 9 | J30: SUG | K30: 5 | P30: 0 | Q30: Potato | R30: Mud | S30: Starch | T30: 3 | U30: =ROUND(2*T30^2*IF(D30="Rare Active",6,IF(D30="Workhorse",2,1))+(K30+M30+O30)/2,0) -> 21 | V30: 120 | W30: =IF(COUNTIF(Plants!$A$2:$A$1000,C30)>0,"yes","")
A31: SP030 | B31: Wild Rice | C31: Zizania aquatica | D31: Base | E31: Wetland | F31: Seed | G31: 8 | H31: 9 | I31: 9 | J31: SUG | K31: 4 | P31: 0 | Q31: Nutty | R31: Grain | S31: Food filler | T31: 4 | U31: =ROUND(2*T31^2*IF(D31="Rare Active",6,IF(D31="Workhorse",2,1))+(K31+M31+O31)/2,0) -> 34 | V31: 300 | W31: =IF(COUNTIF(Plants!$A$2:$A$1000,C31)>0,"yes","")
A32: SP031 | B32: Pickerelweed | C32: Pontederia cordata | D32: Base | E32: Wetland | F32: Seed | G32: 8 | H32: 10 | I32: 9 | J32: SUG | K32: 3 | P32: 0 | Q32: Nutty | R32: Faint | S32: Filler | T32: 3 | U32: =ROUND(2*T32^2*IF(D32="Rare Active",6,IF(D32="Workhorse",2,1))+(K32+M32+O32)/2,0) -> 20 | V32: 300 | W32: =IF(COUNTIF(Plants!$A$2:$A$1000,C32)>0,"yes","")
A33: SP032 | B33: Sweetflag | C33: Acorus calamus | D33: Workhorse | E33: Wetland | F33: Rhizome | G33: 4 | H33: 10 | I33: 0 | J33: VOL | K33: 6 | L33: BIT | M33: 4 | P33: 3 | Q33: Bitter, ginger-like | R33: Spicy perfume | S33: Stimulant / voice clarity | T33: 3 | U33: =ROUND(2*T33^2*IF(D33="Rare Active",6,IF(D33="Workhorse",2,1))+(K33+M33+O33)/2,0) -> 41 | V33: 120 | W33: =IF(COUNTIF(Plants!$A$2:$A$1000,C33)>0,"yes","")
A34: SP033 | B34: Duckweed | C34: Lemna minor | D34: Base | E34: Wetland | F34: Whole | G34: 5 | H34: 9 | I34: 0 | J34: SUG | K34: 1 | L34: MUC | M34: 1 | P34: 0 | Q34: Bland | R34: Pond | S34: Compost accelerant | T34: 1 | U34: =ROUND(2*T34^2*IF(D34="Rare Active",6,IF(D34="Workhorse",2,1))+(K34+M34+O34)/2,0) -> 3 | V34: 40 | W34: =IF(COUNTIF(Plants!$A$2:$A$1000,C34)>0,"yes","")
A35: SP034 | B35: Common Reed | C35: Phragmites australis | D35: Base | E35: Wetland | F35: Root | G35: 3 | H35: 10 | I35: 10 | J35: SUG | K35: 3 | P35: 0 | Q35: Sweet-starchy | R35: Grassy | S35: Filler / straw | T35: 1 | U35: =ROUND(2*T35^2*IF(D35="Rare Active",6,IF(D35="Workhorse",2,1))+(K35+M35+O35)/2,0) -> 4 | V35: 120 | W35: =IF(COUNTIF(Plants!$A$2:$A$1000,C35)>0,"yes","")
A36: SP035 | B36: Field Horsetail | C36: Equisetum arvense | D36: Base | E36: Riverbank | F36: Whole | G36: 4 | H36: 7 | I36: 0 | J36: ACI | K36: 1 | L36: SAP | M36: 1 | P36: 2 | Q36: Gritty | R36: Grassy | S36: Abrasive / polish | T36: 2 | U36: =ROUND(2*T36^2*IF(D36="Rare Active",6,IF(D36="Workhorse",2,1))+(K36+M36+O36)/2,0) -> 9 | V36: 40 | W36: =IF(COUNTIF(Plants!$A$2:$A$1000,C36)>0,"yes","") -> yes
A37: SP036 | B37: Scouring Rush | C37: Equisetum hyemale | D37: Base | E37: Riverbank | F37: Whole | G37: 1 | H37: 12 | I37: 0 | J37: ACI | K37: 1 | P37: 2 | Q37: Gritty | R37: None | S37: Abrasive / tool sharpening | T37: 2 | U37: =ROUND(2*T37^2*IF(D37="Rare Active",6,IF(D37="Workhorse",2,1))+(K37+M37+O37)/2,0) -> 9 | V37: 40 | W37: =IF(COUNTIF(Plants!$A$2:$A$1000,C37)>0,"yes","")
A38: SP037 | B38: Jewelweed | C38: Impatiens capensis | D38: Workhorse | E38: Bottomland Forest | F38: Whole | G38: 6 | H38: 9 | I38: 9 | J38: SAP | K38: 3 | L38: MUC | M38: 3 | P38: 0 | Q38: Watery | R38: Green | S38: Itch & rash wash (counters Poison Ivy) | T38: 2 | U38: =ROUND(2*T38^2*IF(D38="Rare Active",6,IF(D38="Workhorse",2,1))+(K38+M38+O38)/2,0) -> 19 | V38: 40 | W38: =IF(COUNTIF(Plants!$A$2:$A$1000,C38)>0,"yes","") -> yes
A39: SP038 | B39: Stinging Nettle | C39: Urtica dioica | D39: Workhorse | E39: Bottomland Forest | F39: Leaf | G39: 4 | H39: 6 | I39: 8 | J39: FLA | K39: 3 | L39: ACI | M39: 3 | N39: SUG | O39: 2 | P39: 0 | Q39: Rich, green | R39: Spinach | S39: Strength tonic | T39: 2 | U39: =ROUND(2*T39^2*IF(D39="Rare Active",6,IF(D39="Workhorse",2,1))+(K39+M39+O39)/2,0) -> 20 | V39: 45 | W39: =IF(COUNTIF(Plants!$A$2:$A$1000,C39)>0,"yes","") -> yes
A40: SP039 | B40: Wood Nettle | C40: Laportea canadensis | D40: Base | E40: Bottomland Forest | F40: Leaf | G40: 4 | H40: 6 | I40: 8 | J40: ACI | K40: 2 | L40: FLA | M40: 1 | P40: 0 | Q40: Green | R40: Faint | S40: Fiber / filler | T40: 2 | U40: =ROUND(2*T40^2*IF(D40="Rare Active",6,IF(D40="Workhorse",2,1))+(K40+M40+O40)/2,0) -> 10 | V40: 45 | W40: =IF(COUNTIF(Plants!$A$2:$A$1000,C40)>0,"yes","")
...

Sheet Plants
A1: Latin Name | B1: Plant Name | C1: Maps | D1: Growth Form | E1: Life Cycle | F1: Height (m) | G1: Leaf Color | H1: Flower Color | I1: Dormant Color | J1: Green-up DOY | K1: Flower Start DOY | L1: Flower End DOY | M1: Fruit Ripe DOY | N1: Dieback DOY | O1: Winter Form | P1: Crown | Q1: Light Opt | R1: Light Tol | S1: Moist Opt | T1: Moist Tol | U1: Disturb Opt | V1: Disturb Tol | W1: Fert Opt | X1: Fert Tol | Y1: Mow Tolerance | Z1: C-value | AA1: Origin | AB1: Dispersal | AC1: Patch Scale (m) | AD1: Abundance | AE1: Host | AF1: Flower Shape | AG1: Habitat Notes
A2: Cichorium intybus | B2: Chicory | C2: 1 | D2: tallForb | E2: perennial | F2: 1 | G2: #5d7a3e | H2: #7fa6e6 | I2: #8a7a5e | J2: 75 | K2: 170 | L2: 275 | M2: 220 | N2: 300 | O2: rosette | Q2: 1 | R2: 0.35 | S2: 0.35 | T2: 0.3 | U2: 0.55 | V2: 0.35 | W2: 0.45 | X2: 0.35 | Y2: 2 | Z2: 0 | AA2: introduced | AB2: wind | AC2: 6 | AD2: 0.6 | AE2: soilOrGravel | AF2: daisy | AG2: Gravel shoulders and ditch banks; survives twice-yearly ditch mowing.
A3: Daucus carota | B3: Queen Anne's Lace | C3: 1 | D3: tallForb | E3: biennial | F3: 0.9 | G3: #6f8f45 | H3: #f3f1e6 | I3: #8a7a60 | J3: 70 | K3: 165 | L3: 260 | M3: 230 | N3: 300 | O3: rosette | Q3: 1 | R3: 0.35 | S3: 0.4 | T3: 0.3 | U3: 0.45 | V3: 0.3 | W3: 0.4 | X3: 0.35 | Y3: 2 | Z3: 0 | AA3: introduced | AB3: wind | AC3: 8 | AD3: 0.7 | AE3: soilOrGravel | AF3: umbel | AG3: Roadsides and old fields; first-year plants overwinter as ferny rosettes.
A4: Pastinaca sativa | B4: Wild Parsnip | C4: 1 | D4: tallForb | E4: biennial | F4: 1.3 | G4: #7a9a3c | H4: #d8c23a | I4: #9a8a5a | J4: 75 | K4: 150 | L4: 200 | M4: 205 | N4: 260 | O4: rosette | Q4: 1 | R4: 0.35 | S4: 0.5 | T4: 0.3 | U4: 0.4 | V4: 0.3 | W4: 0.55 | X4: 0.3 | Y4: 2 | Z4: 0 | AA4: introduced | AB4: wind | AC4: 10 | AD4: 0.5 | AE4: soil | AF4: umbel | AG4: Spreads along mowed roadsides; sap causes sun burns.
A5: Dipsacus fullonum | B5: Wild Teasel | C5: 1 | D5: tallForb | E5: biennial | F5: 1.8 | G5: #5f7a3a | H5: #b39ad6 | I5: #9a8768 | J5: 70 | K5: 185 | L5: 230 | M5: 245 | N5: 280 | O5: standing | Q5: 1 | R5: 0.35 | S5: 0.55 | T5: 0.3 | U5: 0.4 | V5: 0.3 | W5: 0.5 | X5: 0.3 | Y5: 1 | Z5: 0 | AA5: invasive | AB5: wind | AC5: 12 | AD5: 0.45 | AE5: soil | AF5: globe | AG5: Colonizes ditches; spiny dead heads stand all winter.
A6: Ambrosia artemisiifolia | B6: Common Ragweed | C6: 1 | D6: forb | E6: summerAnnual | F6: 0.9 | G6: #6b8a3a | H6: #a8a65a | I6: #8a7a5a | J6: 110 | K6: 220 | L6: 275 | M6: 260 | N6: 290 | O6: none | Q6: 1 | R6: 0.35 | S6: 0.4 | T6: 0.3 | U6: 0.75 | V6: 0.3 | W6: 0.5 | X6: 0.35 | Y6: 1 | Z6: 0 | AA6: native | AB6: gravity | AC6: 5 | AD6: 0.6 | AE6: soilOrGravel | AF6: plume | AG6: Annual of freshly turned or scraped soil.
A7: Solanum carolinense | B7: Horse Nettle | C7: 1 | D7: forb | E7: perennial | F7: 0.6 | G7: #6a8a42 | H7: #e6ddf0 | I7: #c8b04a | J7: 120 | K7: 150 | L7: 250 | M7: 240 | N7: 285 | O7: standing | Q7: 1 | R7: 0.35 | S7: 0.4 | T7: 0.3 | U7: 0.6 | V7: 0.35 | W7: 0.45 | X7: 0.35 | Y7: 2 | Z7: 0 | AA7: native | AB7: animal | AC7: 6 | AD7: 0.4 | AE7: soil | AF7: daisy | AG7: Rhizomatous pasture weed; yellow berries hang on dead stems in winter.
A8: Verbascum thapsus | B8: Common Mullein | C8: 1 | D8: tallForb | E8: biennial | F8: 1.6 | G8: #9aa58a | H8: #e8d24a | I8: #6e5a40 | J8: 60 | K8: 170 | L8: 245 | M8: 240 | N8: 300 | O8: rosette | Q8: 1 | R8: 0.3 | S8: 0.3 | T8: 0.3 | U8: 0.55 | V8: 0.3 | W8: 0.35 | X8: 0.3 | Y8: 1 | Z8: 0 | AA8: introduced | AB8: gravity | AC8: 8 | AD8: 0.45 | AE8: soilOrGravel | AF8: spike | AG8: Gravelly, dry, disturbed ground; big woolly rosettes are obvious in March.
A9: Rumex crispus | B9: Curly Dock | C9: 1 | D9: tallForb | E9: perennial | F9: 1 | G9: #5f7d36 | H9: #8a6a3a | I9: #7a4a2a | J9: 55 | K9: 140 | L9: 180 | M9: 190 | N9: 320 | O9: rosette | Q9: 1 | R9: 0.4 | S9: 0.6 | T9: 0.3 | U9: 0.5 | V9: 0.35 | W9: 0.6 | X9: 0.3 | Y9: 2 | Z9: 0 | AA9: introduced | AB9: wind | AC9: 6 | AD9: 0.55 | AE9: soil | AF9: plume | AG9: Moist disturbed ground; rusty seed stalks stand through winter.
A10: Equisetum arvense | B10: Field Horsetail | C10: 1 | D10: horsetail | E10: perennial | F10: 0.35 | G10: #6f9a3c | H10: #c8b48a | I10: #8a7a5a | J10: 75 | K10: 75 | L10: 105 | M10: 105 | N10: 300 | O10: none | Q10: 0.85 | R10: 0.4 | S10: 0.75 | T10: 0.25 | U10: 0.35 | V10: 0.35 | W10: 0.45 | X10: 0.35 | Y10: 2 | Z10: 0 | AA10: native | AB10: rhizome | AC10: 5 | AD10: 0.5 | AE10: soilOrGravel | AF10: spike | AG10: Damp ditch bottoms and wet gravel; tan fertile stems in early spring.
A11: Capsella bursa-pastoris | B11: Shepherd's Purse | C11: 1 | D11: rosette | E11: winterAnnual | F11: 0.3 | G11: #6f8f45 | H11: #f5f5f0 | I11: #8a8a5a | J11: 280 | K11: 60 | L11: 150 | M11: 120 | N11: 170 | O11: rosette | Q11: 1 | R11: 0.4 | S11: 0.45 | T11: 0.35 | U11: 0.65 | V11: 0.35 | W11: 0.55 | X11: 0.35 | Y11: 3 | Z11: 0 | AA11: introduced | AB11: gravity | AC11: 3 | AD11: 0.5 | AE11: soilOrGravel | AF11: spike | AG11: Winter annual of bare, trodden soil.
A12: Taraxacum officinale | B12: Dandelion | C12: 1 | D12: rosette | E12: perennial | F12: 0.25 | G12: #5c8a35 | H12: #f2c81e | I12: #5a6a3a | J12: 50 | K12: 80 | L12: 140 | M12: 110 | N12: 340 | O12: rosette | Q12: 0.95 | R12: 0.4 | S12: 0.5 | T12: 0.35 | U12: 0.4 | V12: 0.35 | W12: 0.55 | X12: 0.35 | Y12: 3 | Z12: 0 | AA12: introduced | AB12: wind | AC12: 4 | AD12: 0.75 | AE12: soil | AF12: daisy | AG12: Lawns and anywhere mowed; outcompeted in tall unmowed grass.
A13: Viola sororia | B13: Common Blue Violet | C13: 1 | D13: rosette | E13: perennial | F13: 0.15 | G13: #3f7a3a | H13: #6a4fc9 | I13: #4a5a3a | J13: 75 | K13: 90 | L13: 125 | M13: 140 | N13: 310 | O13: none | Q13: 0.6 | R13: 0.35 | S13: 0.55 | T13: 0.3 | U13: 0.3 | V13: 0.3 | W13: 0.55 | X13: 0.3 | Y13: 3 | Z13: 1 | AA13: native | AB13: ballistic | AC13: 5 | AD13: 0.6 | AE13: soil | AF13: daisy | AG13: Shady lawn edges and under yard trees.
... A68: Silphium laciniatum | B68: Compass Plant | C68: 1 | D68: tallForb | E68: perennial | F68: 2.2 | G68: #5a7a4a | H68: #f0c030 | I68: #5a4a38 | J68: 105 | K68: 190 | L68: 240 | M68: 260 | N68: 300 | O68: standing | Q68: 1 | R68: 0.25 | S68: 0.4 | T68: 0.3 | U68: 0.03 | V68: 0.15 | W68: 0.3 | X68: 0.25 | Y68: 0 | Z68: 8 | AA68: native | AB68: gravity | AC68: 6 | AD68: 0.25 | AE68: soil | AF68: daisy | AG68: Deep-rooted remnant giant; leaves point north–south.
A69: Sassafras albidum | B69: Sassafras | C69: 1 | D69: tree | E69: woody | F69: 8 | G69: #5a8a3a | H69: #e0d460 | I69: #5a5a3a | J69: 105 | K69: 90 | L69: 110 | M69: 230 | N69: 300 | O69: bare | P69: upright | Q69: 0.85 | R69: 0.4 | S69: 0.4 | T69: 0.3 | U69: 0.15 | V69: 0.25 | W69: 0.4 | X69: 0.3 | Y69: 0 | Z69: 2 | AA69: native | AB69: bird | AC69: 6 | AD69: 0.5 | AE69: soil | AF69: cluster | AG69: Fencerow colonies from root suckers.
A70: Diospyros virginiana | B70: Persimmon | C70: 1 | D70: tree | E70: woody | F70: 10 | G70: #4f7a3a | H70: #e8e4c0 | I70: #3a3a34 | J70: 115 | K70: 140 | L70: 160 | M70: 285 | N70: 310 | O70: bare | P70: upright | Q70: 0.9 | R70: 0.4 | S70: 0.45 | T70: 0.35 | U70: 0.15 | V70: 0.25 | W70: 0.4 | X70: 0.3 | Y70: 0 | Z70: 2 | AA70: native | AB70: animal | AC70: 6 | AD70: 0.35 | AE70: soil | AF70: cluster | AG70: Fencerows and old fields; fruit ripens after frost.
A71: Rubus occidentalis | B71: Black Raspberry | C71: 1 | D71: cane | E71: woody | F71: 1.2 | G71: #4f7a35 | H71: #f5f5ef | I71: #a8a0b8 | J71: 80 | K71: 125 | L71: 145 | M71: 175 | N71: 330 | O71: standing | P71: arching | Q71: 0.75 | R71: 0.35 | S71: 0.5 | T71: 0.3 | U71: 0.25 | V71: 0.3 | W71: 0.55 | X71: 0.3 | Y71: 0 | Z71: 2 | AA71: native | AB71: bird | AC71: 5 | AD71: 0.6 | AE71: soil | AF71: daisy | AG71: Bird-sown at fence lines; waxy purple-white canes in winter.
A72: Rubus allegheniensis | B72: Blackberry | C72: 1 | D72: cane | E72: woody | F72: 1.5 | G72: #3f6a30 | H72: #f5f5ef | I72: #6a2a2a | J72: 85 | K72: 140 | L72: 160 | M72: 200 | N72: 330 | O72: standing | P72: arching | Q72: 0.9 | R72: 0.35 | S72: 0.5 | T72: 0.3 | U72: 0.2 | V72: 0.3 | W72: 0.5 | X72: 0.3 | Y72: 0 | Z72: 2 | AA72: native | AB72: bird | AC72: 7 | AD72: 0.65 | AE72: soil | AF72: daisy | AG72: Thorny thickets in sunny fencerow gaps.
A73: Rhus glabra | B73: Smooth Sumac | C73: 1 | D73: shrub | E73: woody | F73: 3 | G73: #4f7a35 | H73: #d8d8a0 | I73: #8a3a2a | J73: 120 | K73: 160 | L73: 180 | M73: 240 | N73: 285 | O73: bare | P73: vase | Q73: 1 | R73: 0.3 | S73: 0.3 | T73: 0.3 | U73: 0.15 | V73: 0.25 | W73: 0.3 | X73: 0.3 | Y73: 0 | Z73: 1 | AA73: native | AB73: bird | AC73: 10 | AD73: 0.45 | AE73: soil | AF73: plume | AG73: Clonal stands creeping into unmowed fields.
A74: Juniperus virginiana | B74: Eastern Red Cedar | C74: 1 | D74: tree | E74: woody | F74: 9 | G74: #27402a | H74: #6a7a5a | I74: #2e4630 | J74: 1 | K74: 60 | L74: 90 | M74: 300 | N74: 999 | O74: evergreen | P74: conifer | Q74: 0.95 | R74: 0.4 | S74: 0.3 | T74: 0.35 | U74: 0.15 | V74: 0.25 | W74: 0.35 | X74: 0.3 | Y74: 0 | Z74: 0 | AA74: native | AB74: bird | AC74: 6 | AD74: 0.85 | AE74: soil | AF74: cluster | AG74: Bird-planted along every fence; invades prairie that isn't burned.
A75: Rosa carolina | B75: Pasture Rose | C75: 1 | D75: cane | E75: woody | F75: 0.7 | G75: #4f7a35 | H75: #e8a0b8 | I75: #8a3a30 | J75: 100 | K75: 140 | L75: 170 | M75: 250 | N75: 310 | O75: standing | P75: arching | Q75: 0.9 | R75: 0.35 | S75: 0.4 | T75: 0.3 | U75: 0.1 | V75: 0.25 | W75: 0.35 | X75: 0.3 | Y75: 0 | Z75: 4 | AA75: native | AB75: bird | AC75: 5 | AD75: 0.35 | AE75: soil | AF75: daisy | AG75: Low thorny clumps in old fencerows; red hips in winter.
A76: Toxicodendron radicans | B76: Poison Ivy | C76: 1 | D76: vine | E76: woody | F76: 0.8 | G76: #3f6a30 | H76: #e0e0b0 | I76: #6a5a48 | J76: 105 | K76: 135 | L76: 150 | M76: 250 | N76: 290 | O76: standing | Q76: 0.6 | R76: 0.4 | S76: 0.5 | T76: 0.35 | U76: 0.2 | V76: 0.3 | W76: 0.55 | X76: 0.3 | Y76: 0 | Z76: 1 | AA76: native | AB76: bird | AC76: 6 | AD76: 0.55 | AE76: soil | AF76: cluster | AG76: Climbs fence posts and trees where birds drop seed.
A77: Parthenocissus quinquefolia | B77: Virginia Creeper | C77: 1 | D77: vine | E77: woody | F77: 0.6 | G77: #4f7a35 | H77: #c8d0a0 | I77: #5a4a3a | J77: 105 | K77: 160 | L77: 180 | M77: 255 | N77: 290 | O77: none | Q77: 0.55 | R77: 0.4 | S77: 0.5 | T77: 0.3 | U77: 0.2 | V77: 0.3 | W77: 0.55 | X77: 0.3 | Y77: 0 | Z77: 2 | AA77: native | AB77: bird | AC77: 6 | AD77: 0.45 | AE77: soil | AF77: cluster | AG77: Five-leaflet vine on fencerow trees; looks like grape until you count.
A78: Vitis riparia | B78: Riverbank Grape | C78: 1 | D78: vine | E78: woody | F78: 1.2 | G78: #5a8a3a | H78: #d8dca0 | I78: #6a4a30 | J78: 105 | K78: 140 | L78: 155 | M78: 245 | N78: 295 | O78: standing | Q78: 0.8 | R78: 0.4 | S78: 0.6 | T78: 0.3 | U78: 0.2 | V78: 0.3 | W78: 0.55 | X78: 0.3 | Y78: 0 | Z78: 2 | AA78: native | AB78: bird | AC78: 7 | AD78: 0.45 | AE78: soil | AF78: cluster | AG78: Shreddy-barked tangles over fencerow shrubs.
A79: Prunus serotina | B79: Wild Cherry | C79: 1 | D79: tree | E79: woody | F79: 10 | G79: #3f6a30 | H79: #f5f5ef | I79: #3a3430 | J79: 100 | K79: 115 | L79: 130 | M79: 205 | N79: 295 | O79: bare | P79: upright | Q79: 0.85 | R79: 0.4 | S79: 0.45 | T79: 0.3 | U79: 0.15 | V79: 0.25 | W79: 0.5 | X79: 0.3 | Y79: 0 | Z79: 1 | AA79: native | AB79: bird | AC79: 6 | AD79: 0.55 | AE79: soil | AF79: cluster | AG79: The commonest bird-planted fencerow tree.
A80: Crataegus mollis | B80: Downy Hawthorn | C80: 1 | D80: tree | E80: woody | F80: 6 | G80: #4f7a35 | H80: #f5f5ef | I80: #4a4038 | J80: 95 | K80: 110 | L80: 125 | M80: 260 | N80: 300 | O80: bare | P80: spreading | Q80: 0.9 | R80: 0.35 | S80: 0.5 | T80: 0.3 | U80: 0.15 | V80: 0.25 | W80: 0.45 | X80: 0.3 | Y80: 0 | Z80: 3 | AA80: native | AB80: bird | AC80: 5 | AD80: 0.4 | AE80: soil | AF80: globe | AG80: Thorny small tree of old pastures and fences.
A81: Morus rubra | B81: Red Mulberry | C81: 1 | D81: tree | E81: woody | F81: 9 | G81: #4f7a35 | H81: #c8d0a0 | I81: #4a4038 | J81: 105 | K81: 105 | L81: 120 | M81: 165 | N81: 300 | O81: bare | P81: spreading | Q81: 0.7 | R81: 0.4 | S81: 0.55 | T81: 0.3 | U81: 0.15 | V81: 0.25 | W81: 0.6 | X81: 0.3 | Y81: 0 | Z81: 5 | AA81: native | AB81: bird | AC81: 5 | AD81: 0.3 | AE81: soil | AF81: cluster | AG81: Fencerow and woods-edge tree; fruit in June.
A82: Juglans nigra | B82: Black Walnut | C82: 1 | D82: tree | E82: woody | F82: 15 | G82: #5a8a3a | H82: #a8b070 | I82: #2e2a26 | J82: 125 | K82: 125 | L82: 140 | M82: 265 | N82: 285 | O82: bare | P82: spreading | Q82: 0.8 | R82: 0.4 | S82: 0.6 | T82: 0.3 | U82: 0.1 | V82: 0.25 | W82: 0.7 | X82: 0.3 | Y82: 0 | Z82: 4 | AA82: native | AB82: caching | AC82: 8 | AD82: 0.45 | AE82: soil | AF82: cluster | AG82: Rich edge soil; squirrels plant the nuts.
A83: Carya ovata | B83: Shagbark Hickory | C83: 1 | D83: tree | E83: woody | F83: 18 | G83: #4f7a35 | H83: #a8b070 | I83: #5a5048 | J83: 110 | K83: 120 | L83: 135 | M83: 275 | N83: 295 | O83: bare | P83: upright | Q83: 0.6 | R83: 0.4 | S83: 0.45 | T83: 0.3 | U83: 0.05 | V83: 0.2 | W83: 0.5 | X83: 0.3 | Y83: 0 | Z83: 4 | AA83: native | AB83: caching | AC83: 8 | AD83: 0.45 | AE83: soil | AF83: cluster | AG83: Upland woods edge; shaggy bark plates.
A84: Quercus alba | B84: White Oak | C84: 1 | D84: tree | E84: woody | F84: 18 | G84: #4f7a35 | H84: #c8c070 | I84: #8a8478 | J84: 110 | K84: 105 | L84: 120 | M84: 270 | N84: 305 | O84: bare | P84: spreading | Q84: 0.6 | R84: 0.4 | S84: 0.4 | T84: 0.3 | U84: 0.05 | V84: 0.2 | W84: 0.45 | X84: 0.3 | Y84: 0 | Z84: 5 | AA84: native | AB84: caching | AC84: 10 | AD84: 0.55 | AE84: soil | AF84: cluster | AG84: The dominant upland tree behind the field.
A85: Acer saccharum | B85: Sugar Maple | C85: 1 | D85: tree | E85: woody | F85: 20 | G85: #4f7a35 | H85: #c8c060 | I85: #4a4440 | J85: 100 | K85: 75 | L85: 95 | M85: 160 | N85: 300 | O85: bare | P85: upright | Q85: 0.4 | R85: 0.4 | S85: 0.5 | T85: 0.3 | U85: 0.05 | V85: 0.2 | W85: 0.6 | X85: 0.3 | Y85: 0 | Z85: 5 | AA85: native | AB85: wind | AC85: 10 | AD85: 0.4 | AE85: soil | AF85: plume | AG85: Shade-tolerant upland tree; tapped for sap in late winter.
A86: Lindera benzoin | B86: Spicebush | C86: 1 | D86: shrub | E86: woody | F86: 2.5 | G86: #4f7a35 | H86: #e8d040 | I86: #5a5040 | J86: 105 | K86: 64 | L86: 98 | M86: 255 | N86: 295 | O86: bare | P86: multistem | Q86: 0.35 | R86: 0.3 | S86: 0.65 | T86: 0.25 | U86: 0.05 | V86: 0.2 | W86: 0.65 | X86: 0.3 | Y86: 0 | Z86: 7 | AA86: native | AB86: bird | AC86: 6 | AD86: 0.55 | AE86: soil | AF86: cluster | AG86: Moist woods edge; yellow bloom on bare twigs in March.
A87: Lonicera maackii | B87: Bush Honeysuckle | C87: 1 | D87: shrub | E87: woody | F87: 4 | G87: #4f8a3a | H87: #f5f2e2 | I87: #4a5a38 | J87: 60 | K87: 125 | L87: 145 | M87: 290 | N87: 330 | O87: bare | P87: multistem | Q87: 0.45 | R87: 0.45 | S87: 0.5 | T87: 0.3 | U87: 0.2 | V87: 0.3 | W87: 0.6 | X87: 0.3 | Y87: 0 | Z87: 0 | AA87: invasive | AB87: bird | AC87: 8 | AD87: 0.75 | AE87: soil | AF87: cluster | AG87: Invasive; first shrub to leaf out in spring, last to drop.
A88: Sambucus canadensis | B88: Elderberry | C88: 1 | D88: shrub | E88: woody | F88: 3 | G88: #5a8a3a | H88: #f5f2e2 | I88: #6a6a5a | J88: 95 | K88: 160 | L88: 185 | M88: 225 | N88: 295 | O88: bare | P88: multistem | Q88: 0.75 | R88: 0.35 | S88: 0.8 | T88: 0.2 | U88: 0.2 | V88: 0.3 | W88: 0.65 | X88: 0.3 | Y88: 0 | Z88: 2 | AA88: native | AB88: bird | AC88: 6 | AD88: 0.5 | AE88: soil | AF88: umbel | AG88: Wet drainage notches at the woods edge and ditch.
A89: Alliaria petiolata | B89: Garlic Mustard | C89: 1 | D89: rosette | E89: biennial | F89: 0.8 | G89: #3f7a30 | H89: #f5f5f0 | I89: #3f6a30 | J89: 60 | K89: 100 | L89: 140 | M89: 170 | N89: 190 | O89: rosette | Q89: 0.35 | R89: 0.35 | S89: 0.55 | T89: 0.3 | U89: 0.2 | V89: 0.3 | W89: 0.6 | X89: 0.3 | Y89: 0 | Z89: 0 | AA89: invasive | AB89: gravity | AC89: 10 | AD89: 0.6 | AE89: soil | AF89: spike | AG89: Invades shaded edges; dark green rosettes all winter.
A90: Galium aparine | B90: Cleavers | C90: 1 | D90: mat | E90: winterAnnual | F90: 0.4 | G90: #6f9a46 | H90: #f5f5f0 | I90: #6f9a46 | J90: 300 | K90: 110 | L90: 140 | M90: 160 | N90: 180 | O90: mat | Q90: 0.5 | R90: 0.35 | S90: 0.6 | T90: 0.3 | U90: 0.25 | V90: 0.3 | W90: 0.7 | X90: 0.3 | Y90: 0 | Z90: 0 | AA90: native | AB90: animal | AC90: 6 | AD90: 0.6 | AE90: soil | AF90: plume | AG90: Sticky sprawl in rich, shaded edges in spring.
A91: Impatiens capensis | B91: Jewelweed | C91: 1 | D91: tallForb | E91: summerAnnual | F91: 1.2 | G91: #6a9a4a | H91: #f08a20 | I91: #8a7a5a | J91: 100 | K91: 195 | L91: 270 | M91: 230 | N91: 285 | O91: none | Q91: 0.45 | R91: 0.35 | S91: 0.85 | T91: 0.2 | U91: 0.2 | V91: 0.3 | W91: 0.6 | X91: 0.3 | Y91: 0 | Z91: 2 | AA91: native | AB91: ballistic | AC91: 6 | AD91: 0.5 | AE91: soil | AF91: bell | AG91: Wet, shaded drainage at the woods edge.
A92: Podophyllum peltatum | B92: Mayapple | C92: 1 | D92: forb | E92: perennial | F92: 0.4 | G92: #4f8a3a | H92: #f5f5ef | I92: #6a6040 | J92: 90 | K92: 110 | L92: 125 | M92: 185 | N92: 200 | O92: none | Q92: 0.35 | R92: 0.3 | S92: 0.55 | T92: 0.3 | U92: 0.05 | V92: 0.2 | W92: 0.6 | X92: 0.3 | Y92: 0 | Z92: 3 | AA92: native | AB92: rhizome | AC92: 12 | AD92: 0.55 | AE92: soil | AF92: daisy | AG92: Colonies of umbrellas under the woods edge; gone by midsummer.
A93: Laetiporus sulphureus | B93: Chicken of the Woods | C93: 1 | D93: fungusBracket | E93: fungus | F93: 0.3 | G93: #f0a030 | H93: #f0c040 | I93: #a07040 | J93: 150 | K93: 150 | L93: 280 | M93: 280 | N93: 290 | O93: none | Q93: 0.6 | R93: 0.5 | S93: 0.6 | T93: 0.4 | U93: 0.1 | V93: 0.4 | W93: 0.6 | X93: 0.4 | Y93: 0 | Z93: 0 | AA93: native | AB93: spores | AC93: 4 | AD93: 0.4 | AE93: wood | AF93: cluster | AG93: Bright shelves on dead and dying oak.
A94: Trametes versicolor | B94: Turkey Tail | C94: 1 | D94: fungusBracket | E94: fungus | F94: 0.08 | G94: #8a7a6a | H94: #b8a890 | I94: #7a6a5a | J94: 1 | K94: 1 | L94: 365 | M94: 365 | N94: 999 | O94: evergreen | Q94: 0.6 | R94: 0.5 | S94: 0.6 | T94: 0.4 | U94: 0.1 | V94: 0.4 | W94: 0.6 | X94: 0.4 | Y94: 0 | Z94: 0 | AA94: native | AB94: spores | AC94: 4 | AD94: 0.8 | AE94: wood | AF94: cluster | AG94: Thin banded brackets on fallen logs, all year.
...

Sheet Compounds
A1: Code | B1: Class | C1: What it is (in game) | D1: Best Extraction | E1: Destroyed / Degraded By | F1: Gameplay Role | G1: Key Interaction | H1: # Species Carrying | I1: Avg Strength
A2: ALK | B2: Alkaloids | C2: Nitrogen bases; strong bodily effects | D2: Acid-water or alcohol | E2: Heat >80°C | F2: Most potent class; narrowest safety margin | G2: Neutralized by TAN (precipitates) | H2: =COUNTIF(Species!$J$2:$J$186,A2)+COUNTIF(Species!$L$2:$L$186,A2)+COUNTIF(Species!$N$2:$N$186,A2) -> 21 | I2: =IFERROR((SUMIF(Species!$J$2:$J$186,A2,Species!$K$2:$K$186)+SUMIF(Species!$L$2:$L$186,A2,Species!$M$2:$M$186)+SUMIF(Species!$N$2:$N$186,A2,Species!$O$2:$O$186))/H2,0) -> 4.6666667
A3: ANT | B3: Anthocyanins | C3: Red-purple-blue pigments | D3: Water / alcohol | E3: Light, high pH | F3: Color shifts with pH — a built-in indicator | G3: Boosted by ACI (reddens) | H3: =COUNTIF(Species!$J$2:$J$186,A3)+COUNTIF(Species!$L$2:$L$186,A3)+COUNTIF(Species!$N$2:$N$186,A3) -> 10 | I3: =IFERROR((SUMIF(Species!$J$2:$J$186,A3,Species!$K$2:$K$186)+SUMIF(Species!$L$2:$L$186,A3,Species!$M$2:$M$186)+SUMIF(Species!$N$2:$N$186,A3,Species!$O$2:$O$186))/H3,0) -> 3.8
A4: ACI | B4: Organic Acids | C4: Sourness; preservation | D4: Water | E4: Stable | F4: Lowers batch pH; extends shelf life | G4: Pulls ALK into water | H4: =COUNTIF(Species!$J$2:$J$186,A4)+COUNTIF(Species!$L$2:$L$186,A4)+COUNTIF(Species!$N$2:$N$186,A4) -> 16 | I4: =IFERROR((SUMIF(Species!$J$2:$J$186,A4,Species!$K$2:$K$186)+SUMIF(Species!$L$2:$L$186,A4,Species!$M$2:$M$186)+SUMIF(Species!$N$2:$N$186,A4,Species!$O$2:$O$186))/H4,0) -> 3.0625
A5: BIT | B5: Bitters | C5: Bitter principles | D5: Water / alcohol | E5: Stable | F5: Digestive actions; hard to mask | G5: Masked by SUG + VOL | H5: =COUNTIF(Species!$J$2:$J$186,A5)+COUNTIF(Species!$L$2:$L$186,A5)+COUNTIF(Species!$N$2:$N$186,A5) -> 19 | I5: =IFERROR((SUMIF(Species!$J$2:$J$186,A5,Species!$K$2:$K$186)+SUMIF(Species!$L$2:$L$186,A5,Species!$M$2:$M$186)+SUMIF(Species!$N$2:$N$186,A5,Species!$O$2:$O$186))/H5,0) -> 4.6315789
A6: COU | B6: Coumarins | C6: Sweet hay scent; some photo-reactive | D6: Alcohol / oil | E6: UV light | F6: Sun-reaction risk in some species | G6: — | H6: =COUNTIF(Species!$J$2:$J$186,A6)+COUNTIF(Species!$L$2:$L$186,A6)+COUNTIF(Species!$N$2:$N$186,A6) -> 3 | I6: =IFERROR((SUMIF(Species!$J$2:$J$186,A6,Species!$K$2:$K$186)+SUMIF(Species!$L$2:$L$186,A6,Species!$M$2:$M$186)+SUMIF(Species!$N$2:$N$186,A6,Species!$O$2:$O$186))/H6,0) -> 3
A7: FLA | B7: Flavonoids | C7: Broad gentle protective compounds | D7: Alcohol | E7: Slow | F7: Stack well; low risk | G7: Synergy with ACI | H7: =COUNTIF(Species!$J$2:$J$186,A7)+COUNTIF(Species!$L$2:$L$186,A7)+COUNTIF(Species!$N$2:$N$186,A7) -> 28 | I7: =IFERROR((SUMIF(Species!$J$2:$J$186,A7,Species!$K$2:$K$186)+SUMIF(Species!$L$2:$L$186,A7,Species!$M$2:$M$186)+SUMIF(Species!$N$2:$N$186,A7,Species!$O$2:$O$186))/H7,0) -> 2.9285714
A8: GLY | B8: Glycosides | C8: Sugar-bound actives (incl. heart & cyanogenic) | D8: Water | E8: Fermentation, crushing | F8: Hidden potency — released by crushing or time | G8: Released by ferment | H8: =COUNTIF(Species!$J$2:$J$186,A8)+COUNTIF(Species!$L$2:$L$186,A8)+COUNTIF(Species!$N$2:$N$186,A8) -> 24 | I8: =IFERROR((SUMIF(Species!$J$2:$J$186,A8,Species!$K$2:$K$186)+SUMIF(Species!$L$2:$L$186,A8,Species!$M$2:$M$186)+SUMIF(Species!$N$2:$N$186,A8,Species!$O$2:$O$186))/H8,0) -> 3.625
A9: LAT | B9: Latex | C9: Milky sap | D9: Alcohol | E9: Air (gums up) | F9: Handle fresh | G9: — | H9: =COUNTIF(Species!$J$2:$J$186,A9)+COUNTIF(Species!$L$2:$L$186,A9)+COUNTIF(Species!$N$2:$N$186,A9) -> 4 | I9: =IFERROR((SUMIF(Species!$J$2:$J$186,A9,Species!$K$2:$K$186)+SUMIF(Species!$L$2:$L$186,A9,Species!$M$2:$M$186)+SUMIF(Species!$N$2:$N$186,A9,Species!$O$2:$O$186))/H9,0) -> 3.5
A10: MUC | B10: Mucilage | C10: Slime; coats and soothes | D10: Cold water | E10: Heat, alcohol | F10: The game's binder & thickener | G10: Ruined by alcohol | H10: =COUNTIF(Species!$J$2:$J$186,A10)+COUNTIF(Species!$L$2:$L$186,A10)+COUNTIF(Species!$N$2:$N$186,A10) -> 15 | I10: =IFERROR((SUMIF(Species!$J$2:$J$186,A10,Species!$K$2:$K$186)+SUMIF(Species!$L$2:$L$186,A10,Species!$M$2:$M$186)+SUMIF(Species!$N$2:$N$186,A10,Species!$O$2:$O$186))/H10,0) -> 4.2666667
A11: PIG | B11: Pigments | C11: Dye molecules | D11: Water (mordant) | E11: Light | F11: Dye path; mordant choice sets color | G11: Fixed by TAN or alum | H11: =COUNTIF(Species!$J$2:$J$186,A11)+COUNTIF(Species!$L$2:$L$186,A11)+COUNTIF(Species!$N$2:$N$186,A11) -> 14 | I11: =IFERROR((SUMIF(Species!$J$2:$J$186,A11,Species!$K$2:$K$186)+SUMIF(Species!$L$2:$L$186,A11,Species!$M$2:$M$186)+SUMIF(Species!$N$2:$N$186,A11,Species!$O$2:$O$186))/H11,0) -> 3.3571429
A12: RES | B12: Resins | C12: Sticky, waxy, oil-soluble | D12: Oil / high-proof alcohol | E12: Stable | F12: Salves & smokes; slow release | G12: Carried by oils & fats | H12: =COUNTIF(Species!$J$2:$J$186,A12)+COUNTIF(Species!$L$2:$L$186,A12)+COUNTIF(Species!$N$2:$N$186,A12) -> 17 | I12: =IFERROR((SUMIF(Species!$J$2:$J$186,A12,Species!$K$2:$K$186)+SUMIF(Species!$L$2:$L$186,A12,Species!$M$2:$M$186)+SUMIF(Species!$N$2:$N$186,A12,Species!$O$2:$O$186))/H12,0) -> 3.7647059
A13: SAP | B13: Saponins | C13: Foaming, soapy | D13: Water | E13: Stable | F13: Emulsifier; mild toxicity | G13: Lets oil & water mix | H13: =COUNTIF(Species!$J$2:$J$186,A13)+COUNTIF(Species!$L$2:$L$186,A13)+COUNTIF(Species!$N$2:$N$186,A13) -> 18 | I13: =IFERROR((SUMIF(Species!$J$2:$J$186,A13,Species!$K$2:$K$186)+SUMIF(Species!$L$2:$L$186,A13,Species!$M$2:$M$186)+SUMIF(Species!$N$2:$N$186,A13,Species!$O$2:$O$186))/H13,0) -> 3.3888889
... A18: RHZ | B18: Rhizine | C18: Mycelial 'blood' (fictional) | D18: Fresh only | E18: Drying destroys it | F18: Binds living things together | G18: Amplifies SPR | H18: =COUNTIF(Species!$J$2:$J$186,A18)+COUNTIF(Species!$L$2:$L$186,A18)+COUNTIF(Species!$N$2:$N$186,A18) -> 4 | I18: =IFERROR((SUMIF(Species!$J$2:$J$186,A18,Species!$K$2:$K$186)+SUMIF(Species!$L$2:$L$186,A18,Species!$M$2:$M$186)+SUMIF(Species!$N$2:$N$186,A18,Species!$O$2:$O$186))/H18,0) -> 6.5

Sheet Processing
A1: Method | B1: Station | C1: Time | D1: Best Inputs | E1: Strengths | F1: Failure Modes | G1: Player-Controlled Variable
A2: Air Dry | B2: Rack | C2: 2–7 days | D2: Leaf, Flower, Whole | E2: Concentrates; keeps most compounds | F2: VOL loss if hung in sun/heat; mold if humid | G2: Drying room humidity & airflow
A3: Oven Dry | B3: Stone oven | C3: 2 hrs | D3: Root, Bark, Seed | E3: Fast | F3: Destroys VOL & RHZ; scorches above set temp | G3: Dial temperature
A4: Grind | B4: Mortar & pestle | C4: Hand motion | D4: Any dried part | E4: Raises extraction yield; releases GLY | F4: Over-grinding heats & loses VOL | G4: Physical grind count (VR gesture)
A5: Cold Infusion | B5: Jar + water | C5: 12 hrs | D5: MUC plants | E5: Pulls mucilage intact | F5: Weak on everything else | G5: Steep time
A6: Hot Infusion (tea) | B6: Kettle | C6: 5–15 min | D6: Leaf, Flower | E6: Fast water extract | F6: Pulls TAN — over-steep = harsh | G6: Steep time & temp
A7: Decoction | B7: Pot | C7: 20–60 min simmer | D7: Root, Bark, Fruiting body | E7: Extracts tough material | F7: Boils off VOL; kills MUC | G7: Simmer time; reduce volume
A8: Tincture | B8: Spirit jar | C8: 14–28 days | D8: Most | E8: Long shelf life; pulls ALK, RES, FLA | F8: Kills MUC; needs spirit (distilled) | G8: Proof % and macerate days
A9: Acetum | B9: Vinegar jar | C9: 14 days | D9: ALK & mineral plants | E9: Pulls ALK; no alcohol needed | F9: Weaker than tincture | G9: Vinegar made in-house from ferments
A10: Infused Oil | B10: Oil jar / double boiler | C10: 2–6 weeks or 4 hrs warm | D10: RES, VOL plants | E10: Salve base | F10: Rancid if water present (fresh herb) | G10: Dryness of input
A11: Salve | B11: Double boiler + beeswax | C11: 30 min | D11: Infused oil | E11: Shelf-stable topical | F11: Wax ratio sets hardness | G11: Oil:wax ratio
A12: Syrup | B12: Pot + honey/sugar | C12: 20 min | D12: Decoctions, fruit | E12: Masks bitterness; preserves | F12: Ferments if under-sugared | G12: Sugar ratio
... A18: Graft | B18: Living altar | C18: 1 season | D18: Garden plants + Graftwort | E18: Hybrid species with merged compounds | F18: Rejection kills both | G18: Compatibility score

Sheet Seasonal Calendar
A1: Species | B1: Part | C1: Jan | D1: Feb | E1: Mar | F1: Apr | G1: May | H1: Jun | I1: Jul | J1: Aug | K1: Sep | L1: Oct | M1: Nov | N1: Dec
A2: =Species!B2 -> Lamb's Quarters | B2: =Species!F2 -> Leaf | C2: =IF(Species!$G2<=Species!$H2,IF(AND(1>=Species!$G2,1<=Species!$H2),"H",""),IF(OR(1>=Species!$G2,1<=Species!$H2),"H",""))&IF(Species!$I2=1,"S","") | D2: =IF(Species!$G2<=Species!$H2,IF(AND(2>=Species!$G2,2<=Species!$H2),"H",""),IF(OR(2>=Species!$G2,2<=Species!$H2),"H",""))&IF(Species!$I2=2,"S","") | E2: =IF(Species!$G2<=Species!$H2,IF(AND(3>=Species!$G2,3<=Species!$H2),"H",""),IF(OR(3>=Species!$G2,3<=Species!$H2),"H",""))&IF(Species!$I2=3,"S","") | F2: =IF(Species!$G2<=Species!$H2,IF(AND(4>=Species!$G2,4<=Species!$H2),"H",""),IF(OR(4>=Species!$G2,4<=Species!$H2),"H",""))&IF(Species!$I2=4,"S","") | G2: =IF(Species!$G2<=Species!$H2,IF(AND(5>=Species!$G2,5<=Species!$H2),"H",""),IF(OR(5>=Species!$G2,5<=Species!$H2),"H",""))&IF(Species!$I2=5,"S","") -> H | H2: =IF(Species!$G2<=Species!$H2,IF(AND(6>=Species!$G2,6<=Species!$H2),"H",""),IF(OR(6>=Species!$G2,6<=Species!$H2),"H",""))&IF(Species!$I2=6,"S","") -> H | I2: =IF(Species!$G2<=Species!$H2,IF(AND(7>=Species!$G2,7<=Species!$H2),"H",""),IF(OR(7>=Species!$G2,7<=Species!$H2),"H",""))&IF(Species!$I2=7,"S","") -> H | J2: =IF(Species!$G2<=Species!$H2,IF(AND(8>=Species!$G2,8<=Species!$H2),"H",""),IF(OR(8>=Species!$G2,8<=Species!$H2),"H",""))&IF(Species!$I2=8,"S","") -> H | K2: =IF(Species!$G2<=Species!$H2,IF(AND(9>=Species!$G2,9<=Species!$H2),"H",""),IF(OR(9>=Species!$G2,9<=Species!$H2),"H",""))&IF(Species!$I2=9,"S","") -> S | L2: =IF(Species!$G2<=Species!$H2,IF(AND(10>=Species!$G2,10<=Species!$H2),"H",""),IF(OR(10>=Species!$G2,10<=Species!$H2),"H",""))&IF(Species!$I2=10,"S","") | M2: =IF(Species!$G2<=Species!$H2,IF(AND(11>=Species!$G2,11<=Species!$H2),"H",""),IF(OR(11>=Species!$G2,11<=Species!$H2),"H",""))&IF(Species!$I2=11,"S","") | N2: =IF(Species!$G2<=Species!$H2,IF(AND(12>=Species!$G2,12<=Species!$H2),"H",""),IF(OR(12>=Species!$G2,12<=Species!$H2),"H",""))&IF(Species!$I2=12,"S","")
A3: =Species!B3 -> Chickweed | B3: =Species!F3 -> Whole | C3: =IF(Species!$G3<=Species!$H3,IF(AND(1>=Species!$G3,1<=Species!$H3),"H",""),IF(OR(1>=Species!$G3,1<=Species!$H3),"H",""))&IF(Species!$I3=1,"S","") | D3: =IF(Species!$G3<=Species!$H3,IF(AND(2>=Species!$G3,2<=Species!$H3),"H",""),IF(OR(2>=Species!$G3,2<=Species!$H3),"H",""))&IF(Species!$I3=2,"S","") | E3: =IF(Species!$G3<=Species!$H3,IF(AND(3>=Species!$G3,3<=Species!$H3),"H",""),IF(OR(3>=Species!$G3,3<=Species!$H3),"H",""))&IF(Species!$I3=3,"S","") -> H | F3: =IF(Species!$G3<=Species!$H3,IF(AND(4>=Species!$G3,4<=Species!$H3),"H",""),IF(OR(4>=Species!$G3,4<=Species!$H3),"H",""))&IF(Species!$I3=4,"S","") -> H | G3: =IF(Species!$G3<=Species!$H3,IF(AND(5>=Species!$G3,5<=Species!$H3),"H",""),IF(OR(5>=Species!$G3,5<=Species!$H3),"H",""))&IF(Species!$I3=5,"S","") -> HS | H3: =IF(Species!$G3<=Species!$H3,IF(AND(6>=Species!$G3,6<=Species!$H3),"H",""),IF(OR(6>=Species!$G3,6<=Species!$H3),"H",""))&IF(Species!$I3=6,"S","") | I3: =IF(Species!$G3<=Species!$H3,IF(AND(7>=Species!$G3,7<=Species!$H3),"H",""),IF(OR(7>=Species!$G3,7<=Species!$H3),"H",""))&IF(Species!$I3=7,"S","") | J3: =IF(Species!$G3<=Species!$H3,IF(AND(8>=Species!$G3,8<=Species!$H3),"H",""),IF(OR(8>=Species!$G3,8<=Species!$H3),"H",""))&IF(Species!$I3=8,"S","") | K3: =IF(Species!$G3<=Species!$H3,IF(AND(9>=Species!$G3,9<=Species!$H3),"H",""),IF(OR(9>=Species!$G3,9<=Species!$H3),"H",""))&IF(Species!$I3=9,"S","") | L3: =IF(Species!$G3<=Species!$H3,IF(AND(10>=Species!$G3,10<=Species!$H3),"H",""),IF(OR(10>=Species!$G3,10<=Species!$H3),"H",""))&IF(Species!$I3=10,"S","") | M3: =IF(Species!$G3<=Species!$H3,IF(AND(11>=Species!$G3,11<=Species!$H3),"H",""),IF(OR(11>=Species!$G3,11<=Species!$H3),"H",""))&IF(Species!$I3=11,"S","") | N3: =IF(Species!$G3<=Species!$H3,IF(AND(12>=Species!$G3,12<=Species!$H3),"H",""),IF(OR(12>=Species!$G3,12<=Species!$H3),"H",""))&IF(Species!$I3=12,"S","")
A4: =Species!B4 -> Purple Deadnettle | B4: =Species!F4 -> Whole | C4: =IF(Species!$G4<=Species!$H4,IF(AND(1>=Species!$G4,1<=Species!$H4),"H",""),IF(OR(1>=Species!$G4,1<=Species!$H4),"H",""))&IF(Species!$I4=1,"S","") | D4: =IF(Species!$G4<=Species!$H4,IF(AND(2>=Species!$G4,2<=Species!$H4),"H",""),IF(OR(2>=Species!$G4,2<=Species!$H4),"H",""))&IF(Species!$I4=2,"S","") | E4: =IF(Species!$G4<=Species!$H4,IF(AND(3>=Species!$G4,3<=Species!$H4),"H",""),IF(OR(3>=Species!$G4,3<=Species!$H4),"H",""))&IF(Species!$I4=3,"S","") -> H | F4: =IF(Species!$G4<=Species!$H4,IF(AND(4>=Species!$G4,4<=Species!$H4),"H",""),IF(OR(4>=Species!$G4,4<=Species!$H4),"H",""))&IF(Species!$I4=4,"S","") -> H | G4: =IF(Species!$G4<=Species!$H4,IF(AND(5>=Species!$G4,5<=Species!$H4),"H",""),IF(OR(5>=Species!$G4,5<=Species!$H4),"H",""))&IF(Species!$I4=5,"S","") -> HS | H4: =IF(Species!$G4<=Species!$H4,IF(AND(6>=Species!$G4,6<=Species!$H4),"H",""),IF(OR(6>=Species!$G4,6<=Species!$H4),"H",""))&IF(Species!$I4=6,"S","") | I4: =IF(Species!$G4<=Species!$H4,IF(AND(7>=Species!$G4,7<=Species!$H4),"H",""),IF(OR(7>=Species!$G4,7<=Species!$H4),"H",""))&IF(Species!$I4=7,"S","") | J4: =IF(Species!$G4<=Species!$H4,IF(AND(8>=Species!$G4,8<=Species!$H4),"H",""),IF(OR(8>=Species!$G4,8<=Species!$H4),"H",""))&IF(Species!$I4=8,"S","") | K4: =IF(Species!$G4<=Species!$H4,IF(AND(9>=Species!$G4,9<=Species!$H4),"H",""),IF(OR(9>=Species!$G4,9<=Species!$H4),"H",""))&IF(Species!$I4=9,"S","") | L4: =IF(Species!$G4<=Species!$H4,IF(AND(10>=Species!$G4,10<=Species!$H4),"H",""),IF(OR(10>=Species!$G4,10<=Species!$H4),"H",""))&IF(Species!$I4=10,"S","") | M4: =IF(Species!$G4<=Species!$H4,IF(AND(11>=Species!$G4,11<=Species!$H4),"H",""),IF(OR(11>=Species!$G4,11<=Species!$H4),"H",""))&IF(Species!$I4=11,"S","") | N4: =IF(Species!$G4<=Species!$H4,IF(AND(12>=Species!$G4,12<=Species!$H4),"H",""),IF(OR(12>=Species!$G4,12<=Species!$H4),"H",""))&IF(Species!$I4=12,"S","")
A5: =Species!B5 -> Henbit | B5: =Species!F5 -> Whole | C5: =IF(Species!$G5<=Species!$H5,IF(AND(1>=Species!$G5,1<=Species!$H5),"H",""),IF(OR(1>=Species!$G5,1<=Species!$H5),"H",""))&IF(Species!$I5=1,"S","") | D5: =IF(Species!$G5<=Species!$H5,IF(AND(2>=Species!$G5,2<=Species!$H5),"H",""),IF(OR(2>=Species!$G5,2<=Species!$H5),"H",""))&IF(Species!$I5=2,"S","") | E5: =IF(Species!$G5<=Species!$H5,IF(AND(3>=Species!$G5,3<=Species!$H5),"H",""),IF(OR(3>=Species!$G5,3<=Species!$H5),"H",""))&IF(Species!$I5=3,"S","") -> H | F5: =IF(Species!$G5<=Species!$H5,IF(AND(4>=Species!$G5,4<=Species!$H5),"H",""),IF(OR(4>=Species!$G5,4<=Species!$H5),"H",""))&IF(Species!$I5=4,"S","") -> H | G5: =IF(Species!$G5<=Species!$H5,IF(AND(5>=Species!$G5,5<=Species!$H5),"H",""),IF(OR(5>=Species!$G5,5<=Species!$H5),"H",""))&IF(Species!$I5=5,"S","") -> HS | H5: =IF(Species!$G5<=Species!$H5,IF(AND(6>=Species!$G5,6<=Species!$H5),"H",""),IF(OR(6>=Species!$G5,6<=Species!$H5),"H",""))&IF(Species!$I5=6,"S","") | I5: =IF(Species!$G5<=Species!$H5,IF(AND(7>=Species!$G5,7<=Species!$H5),"H",""),IF(OR(7>=Species!$G5,7<=Species!$H5),"H",""))&IF(Species!$I5=7,"S","") | J5: =IF(Species!$G5<=Species!$H5,IF(AND(8>=Species!$G5,8<=Species!$H5),"H",""),IF(OR(8>=Species!$G5,8<=Species!$H5),"H",""))&IF(Species!$I5=8,"S","") | K5: =IF(Species!$G5<=Species!$H5,IF(AND(9>=Species!$G5,9<=Species!$H5),"H",""),IF(OR(9>=Species!$G5,9<=Species!$H5),"H",""))&IF(Species!$I5=9,"S","") | L5: =IF(Species!$G5<=Species!$H5,IF(AND(10>=Species!$G5,10<=Species!$H5),"H",""),IF(OR(10>=Species!$G5,10<=Species!$H5),"H",""))&IF(Species!$I5=10,"S","") | M5: =IF(Species!$G5<=Species!$H5,IF(AND(11>=Species!$G5,11<=Species!$H5),"H",""),IF(OR(11>=Species!$G5,11<=Species!$H5),"H",""))&IF(Species!$I5=11,"S","") | N5: =IF(Species!$G5<=Species!$H5,IF(AND(12>=Species!$G5,12<=Species!$H5),"H",""),IF(OR(12>=Species!$G5,12<=Species!$H5),"H",""))&IF(Species!$I5=12,"S","")
A6: =Species!B6 -> Dandelion | B6: =Species!F6 -> Root | C6: =IF(Species!$G6<=Species!$H6,IF(AND(1>=Species!$G6,1<=Species!$H6),"H",""),IF(OR(1>=Species!$G6,1<=Species!$H6),"H",""))&IF(Species!$I6=1,"S","") | D6: =IF(Species!$G6<=Species!$H6,IF(AND(2>=Species!$G6,2<=Species!$H6),"H",""),IF(OR(2>=Species!$G6,2<=Species!$H6),"H",""))&IF(Species!$I6=2,"S","") | E6: =IF(Species!$G6<=Species!$H6,IF(AND(3>=Species!$G6,3<=Species!$H6),"H",""),IF(OR(3>=Species!$G6,3<=Species!$H6),"H",""))&IF(Species!$I6=3,"S","") -> H | F6: =IF(Species!$G6<=Species!$H6,IF(AND(4>=Species!$G6,4<=Species!$H6),"H",""),IF(OR(4>=Species!$G6,4<=Species!$H6),"H",""))&IF(Species!$I6=4,"S","") -> H | G6: =IF(Species!$G6<=Species!$H6,IF(AND(5>=Species!$G6,5<=Species!$H6),"H",""),IF(OR(5>=Species!$G6,5<=Species!$H6),"H",""))&IF(Species!$I6=5,"S","") -> HS | H6: =IF(Species!$G6<=Species!$H6,IF(AND(6>=Species!$G6,6<=Species!$H6),"H",""),IF(OR(6>=Species!$G6,6<=Species!$H6),"H",""))&IF(Species!$I6=6,"S","") -> H | I6: =IF(Species!$G6<=Species!$H6,IF(AND(7>=Species!$G6,7<=Species!$H6),"H",""),IF(OR(7>=Species!$G6,7<=Species!$H6),"H",""))&IF(Species!$I6=7,"S","") -> H | J6: =IF(Species!$G6<=Species!$H6,IF(AND(8>=Species!$G6,8<=Species!$H6),"H",""),IF(OR(8>=Species!$G6,8<=Species!$H6),"H",""))&IF(Species!$I6=8,"S","") -> H | K6: =IF(Species!$G6<=Species!$H6,IF(AND(9>=Species!$G6,9<=Species!$H6),"H",""),IF(OR(9>=Species!$G6,9<=Species!$H6),"H",""))&IF(Species!$I6=9,"S","") -> H | L6: =IF(Species!$G6<=Species!$H6,IF(AND(10>=Species!$G6,10<=Species!$H6),"H",""),IF(OR(10>=Species!$G6,10<=Species!$H6),"H",""))&IF(Species!$I6=10,"S","") -> H | M6: =IF(Species!$G6<=Species!$H6,IF(AND(11>=Species!$G6,11<=Species!$H6),"H",""),IF(OR(11>=Species!$G6,11<=Species!$H6),"H",""))&IF(Species!$I6=11,"S","") -> H | N6: =IF(Species!$G6<=Species!$H6,IF(AND(12>=Species!$G6,12<=Species!$H6),"H",""),IF(OR(12>=Species!$G6,12<=Species!$H6),"H",""))&IF(Species!$I6=12,"S","")
A7: =Species!B7 -> Common Blue Violet | B7: =Species!F7 -> Leaf | C7: =IF(Species!$G7<=Species!$H7,IF(AND(1>=Species!$G7,1<=Species!$H7),"H",""),IF(OR(1>=Species!$G7,1<=Species!$H7),"H",""))&IF(Species!$I7=1,"S","") | D7: =IF(Species!$G7<=Species!$H7,IF(AND(2>=Species!$G7,2<=Species!$H7),"H",""),IF(OR(2>=Species!$G7,2<=Species!$H7),"H",""))&IF(Species!$I7=2,"S","") | E7: =IF(Species!$G7<=Species!$H7,IF(AND(3>=Species!$G7,3<=Species!$H7),"H",""),IF(OR(3>=Species!$G7,3<=Species!$H7),"H",""))&IF(Species!$I7=3,"S","") -> H | F7: =IF(Species!$G7<=Species!$H7,IF(AND(4>=Species!$G7,4<=Species!$H7),"H",""),IF(OR(4>=Species!$G7,4<=Species!$H7),"H",""))&IF(Species!$I7=4,"S","") -> H | G7: =IF(Species!$G7<=Species!$H7,IF(AND(5>=Species!$G7,5<=Species!$H7),"H",""),IF(OR(5>=Species!$G7,5<=Species!$H7),"H",""))&IF(Species!$I7=5,"S","") -> H | H7: =IF(Species!$G7<=Species!$H7,IF(AND(6>=Species!$G7,6<=Species!$H7),"H",""),IF(OR(6>=Species!$G7,6<=Species!$H7),"H",""))&IF(Species!$I7=6,"S","") -> HS | I7: =IF(Species!$G7<=Species!$H7,IF(AND(7>=Species!$G7,7<=Species!$H7),"H",""),IF(OR(7>=Species!$G7,7<=Species!$H7),"H",""))&IF(Species!$I7=7,"S","") | J7: =IF(Species!$G7<=Species!$H7,IF(AND(8>=Species!$G7,8<=Species!$H7),"H",""),IF(OR(8>=Species!$G7,8<=Species!$H7),"H",""))&IF(Species!$I7=8,"S","") | K7: =IF(Species!$G7<=Species!$H7,IF(AND(9>=Species!$G7,9<=Species!$H7),"H",""),IF(OR(9>=Species!$G7,9<=Species!$H7),"H",""))&IF(Species!$I7=9,"S","") | L7: =IF(Species!$G7<=Species!$H7,IF(AND(10>=Species!$G7,10<=Species!$H7),"H",""),IF(OR(10>=Species!$G7,10<=Species!$H7),"H",""))&IF(Species!$I7=10,"S","") | M7: =IF(Species!$G7<=Species!$H7,IF(AND(11>=Species!$G7,11<=Species!$H7),"H",""),IF(OR(11>=Species!$G7,11<=Species!$H7),"H",""))&IF(Species!$I7=11,"S","") | N7: =IF(Species!$G7<=Species!$H7,IF(AND(12>=Species!$G7,12<=Species!$H7),"H",""),IF(OR(12>=Species!$G7,12<=Species!$H7),"H",""))&IF(Species!$I7=12,"S","")
A8: =Species!B8 -> Cleavers | B8: =Species!F8 -> Whole | C8: =IF(Species!$G8<=Species!$H8,IF(AND(1>=Species!$G8,1<=Species!$H8),"H",""),IF(OR(1>=Species!$G8,1<=Species!$H8),"H",""))&IF(Species!$I8=1,"S","") | D8: =IF(Species!$G8<=Species!$H8,IF(AND(2>=Species!$G8,2<=Species!$H8),"H",""),IF(OR(2>=Species!$G8,2<=Species!$H8),"H",""))&IF(Species!$I8=2,"S","") | E8: =IF(Species!$G8<=Species!$H8,IF(AND(3>=Species!$G8,3<=Species!$H8),"H",""),IF(OR(3>=Species!$G8,3<=Species!$H8),"H",""))&IF(Species!$I8=3,"S","") | F8: =IF(Species!$G8<=Species!$H8,IF(AND(4>=Species!$G8,4<=Species!$H8),"H",""),IF(OR(4>=Species!$G8,4<=Species!$H8),"H",""))&IF(Species!$I8=4,"S","") -> H | G8: =IF(Species!$G8<=Species!$H8,IF(AND(5>=Species!$G8,5<=Species!$H8),"H",""),IF(OR(5>=Species!$G8,5<=Species!$H8),"H",""))&IF(Species!$I8=5,"S","") -> H | H8: =IF(Species!$G8<=Species!$H8,IF(AND(6>=Species!$G8,6<=Species!$H8),"H",""),IF(OR(6>=Species!$G8,6<=Species!$H8),"H",""))&IF(Species!$I8=6,"S","") -> HS | I8: =IF(Species!$G8<=Species!$H8,IF(AND(7>=Species!$G8,7<=Species!$H8),"H",""),IF(OR(7>=Species!$G8,7<=Species!$H8),"H",""))&IF(Species!$I8=7,"S","") | J8: =IF(Species!$G8<=Species!$H8,IF(AND(8>=Species!$G8,8<=Species!$H8),"H",""),IF(OR(8>=Species!$G8,8<=Species!$H8),"H",""))&IF(Species!$I8=8,"S","") | K8: =IF(Species!$G8<=Species!$H8,IF(AND(9>=Species!$G8,9<=Species!$H8),"H",""),IF(OR(9>=Species!$G8,9<=Species!$H8),"H",""))&IF(Species!$I8=9,"S","") | L8: =IF(Species!$G8<=Species!$H8,IF(AND(10>=Species!$G8,10<=Species!$H8),"H",""),IF(OR(10>=Species!$G8,10<=Species!$H8),"H",""))&IF(Species!$I8=10,"S","") | M8: =IF(Species!$G8<=Species!$H8,IF(AND(11>=Species!$G8,11<=Species!$H8),"H",""),IF(OR(11>=Species!$G8,11<=Species!$H8),"H",""))&IF(Species!$I8=11,"S","") | N8: =IF(Species!$G8<=Species!$H8,IF(AND(12>=Species!$G8,12<=Species!$H8),"H",""),IF(OR(12>=Species!$G8,12<=Species!$H8),"H",""))&IF(Species!$I8=12,"S","")
